Workbook
Name NumeroColumna: 7
Name NumeroFila: 3
Name Regiones: [1]Datos!$E$1:$E$15

Sheet Portada

Sheet 0
B12: La siguiente herramienta tiene por objetivo que usted implemente la actualización del protocolo TMERT (MINSAL, 2024), considerando los pasos establecidos por el protocolo. Está diseñada de manera tal que usted siga las instrucciones necesarias para completar el proceso de identificacion inicial y avanzada, de una forma sencilla y práctica, evitando potenciales errores en el trascurso de la aplicación.
B13: PASOS A SEGUIR
B16: 1.- En el apartado ANTECEDENTES GENERALES debe completar la información relacionada con la empresa y sus sucursales o centros de trabajo.
B17: 2.- En el apartado CARACTERIZACIÓN DEL RIESGO usted deberá identificar puestos de trabajo y tareas los cuales posteriormente aplicará la identificación inicial y avanzada. Es importante llenar todos los campos ya que se identifican los determinantes de la exposición.
B18: 3.- En el apartado IDENTIFICACIÓN INICIAL usted deberá aplicar a cada puesto de trabajo, las 7 preguntas iniciales, con el objetivo de detectar la presencia de factores de riesgos de TMERT.
B19: 4. En el apartado IDENTIFICACION AVANZADA se dispondrá de las tablas de identificación avanzada para condiciones aceptables y críticas, por cada factor de riesgo.
B21: ¡ IMPORTANTE ! Para efectos de solicitar una evaluación específica del riesgo a la ACHS, deberá haber completado todos estos pasos.

Sheet 1
B13: 1. ANTECEDENTES DE LA EMPRESA
B15: Razón Social | J15: RUT Empresa
B17: Actividad Económica | J17: Código CIIU
B19: Dirección | J19: Comuna
B21: Nombre Representante Legal
B23: Organismo administrador al que está adherido | J23: Fecha inicio
B25: 2.- CENTRO DE TRABAJO O LUGAR DE TRABAJO
B27: Nombre del centro de trabajo
B29: Dirección | J29: Comuna
B31: Nº de trabajadores centro de trabajo | E31: Hombres | J31: Mujeres
B33: 3.- RESPONSABLE IMPLEMENTACIÓN PROTOCOLO
B35: Nombre responsable
B37: Cargo
B39: Correo electrónico | K39: Teléfono

Sheet 2
B12: N° | C12: Área de trabajo | D12: Puesto de trabajo | E12: Tareas del puesto de trabajo | F12: Descripción de la tarea | G12: Horario de funcionamiento | H12: Horas extras | J12: N° Trabajadores Expuestos | L12: Tipo de contrato | M12: Tipo de remuneración | N12: Duración (min) | O12: Pausas de Trabajo | P12: Rotación de tarea | Q12: Equipos y Herramienta | R12: Características de los ambientes y espacios de trabajo (Espacios, barreras arquitectónicas, flujo de tránsito) | S12: Características y disposición espacial del puesto de trabajo (Ubicación de los elementos de trabajo, disposición física del espacio de trabajo) | T12: Características y herramientas utilizadas (Descripción de equipos, herramientas utilizadas, herramientas vibrantes, uso de EPP)
H13: Por dia | I13: Por semana | J13: Hombre | K13: Mujer
B14: 1 | C14: Packing | D14: Seleccionadora línea cítricos 1 | E14: Empacado | F14: Seleción desde cinta transportadora de la fruta y disponerla en las cajas. | G14: 8:00 a 16:00 | H14: 0 | I14: 0 | J14: 6 | K14: 6 | L14: Indefinido | M14: fijo + bono producción | N14: 300 | O14: 1 pausa (10:00 a 10:10) | P14: NO | Q14: --- | R14: linea de producción (cinta transportadora) con 6 trabajadores x lado. | S14: mesón seleccionador a una altura de 95 cm y bandeja superior portadora de caja a 140 cm | T14: Sin uso de equipos o herramientas manuales | U14: =IF(D14='3'!D14, VLOOKUP(C14, '3'!B12:D19, 10, FALSE)," ")
B15: 2 | C15: Faena | D15: Operador excavadora | E15: carga de camión | F15: Operación de excavadora para carga de camiones con tierra. | G15: 8:00 a 18:00 | H15: 2 | I15: 10 | J15: 1 | L15: plazo fijo | M15: variable | N15: 500 | O15: 2 pausas (11:00 a 11:15 y 16:00 a 16:15) | P15: NO | Q15: Excavadora Volvo EC750E | R15: --- | S15: --- | T15: Excavadora Volvo Modelo EC750E. Esta es una excavadora de oruga y su año de fabricacion es 2020.
B16: 3 | C16: area 3 | D16: puesto 3 | E16: tarea 3
B17: 4 | C17: area 4 | D17: puesto 4 | E17: tarea 4
B18: 5 | C18: area 5 | D18: puesto 5 | E18: tarea 5
B19: 6 | C19: area 6 | D19: puesto 6 | E19: tarea 6
B20: 7 | C20: area 7 | D20: puesto 7 | E20: tarea 7
B21: 8 | C21: area 8 | D21: puesto 8 | E21: tarea 8
B22: 9 | C22: area 9 | D22: puesto 9 | E22: tarea 9
B23: 10 | C23: area 10 | D23: puesto 10 | E23: tarea 10
B24: 11 | C24: area 11 | D24: puesto 11 | E24: tarea 11
B25: 12 | C25: area 12 | D25: puesto 12 | E25: tarea 12
B26: 13 | C26: area 13 | D26: puesto 13 | E26: tarea 13
B27: 14 | C27: area 14 | D27: puesto 14 | E27: tarea 14
... B212: 199 | C212: area 199 | D212: puesto 199 | E212: tarea 199

Sheet 3
B12: N° | C12: Puesto de trabajo | D12: Tareas del puesto de trabajo | E12: Trabajo repetitivo de miembros superiores. | F12: Postura de trabajo estática | G12: Manipulación manual de cargas | I12: Manejo manual de pacientes / personas | J12: Vibración de cuerpo completo | K12: Vibración segmento mano – brazo | L12: Resultado identificación inicial
E13: ¿Existe una o más tareas donde utilice las manos y miembros superiores con una duración total de una hora o más durante la jornada laboral y con un tiempo total de 5 o más horas a la semana? Donde tenga que movilizar, levantar, empujar, encajar, sostener, posicionar, armar, limpiar, apretar, lanzar, cortar, presionar, desarmar, atornillar, desatornillar, digitar con presión, comprimir, ubicar, moldear, traccionar. | F13: ¿Existen posturas de trabajo estáticas de cabeza/cuello, tronco y/o miembros superiores e inferiores, mantenidas por más de 4 segundos consecutivamente? Donde se observe estar sentado, cabeza inclinada hacia adelante o atrás, mirada situada en planos bajo nivel medio de tórax o pecho, cabeza rotada permanentemente hacia algún lado, mirada situada en planos sobre el nivel de cabeza, hombros situados por delante de las caderas de manera continua, tronco rotado o inclinado para sostener o movilizar objetos. | G13: Para el Levantamiento/Descenso/Transporte: ¿Existe levantamiento, descenso o transporte manual de un objeto de 3kg o más? Se observa que levanta, sostiene, trasporta, desplaza, moviliza, ubica con precisión ordenando, empuja, arrastra o tracciona, apila, paletiza. | H13: Tracción/Empuje ¿Existe empuje o arrastre de una carga utilizando el cuerpo completo con 1 o 2 manos? Se observa el empuje y/o arrastre de diferentes maneras carros, plataformas con rueda, superficies deslizantes, detención de objetos en movimiento, camillas, camas, sillas de rueda, paletizadores, grúas de uso manual mecanizadas, formas de tracción y empuje hechizas, carretillas. No se considera empuje y arrastre carros motorizados y controlados manualmente (conducción) | I13: ¿Se realiza alguna actividad que requiere fuerza para empujar, tirar, levantar, descender, transferir o de alguna manera mover o sostener una persona o parte del cuerpo de una persona? *NOTA: La condición a identificar debe incluir la actividad de manipulación, ya sea que se realice con o sin dispositivos de asistencia. Esta condición está determinada por el riesgo asociado a las características de la carga humana que requiere control sensible de la masa corporal por parte del operador. | J13: ¿Están los trabajadores/as expuestos/as a vibraciones por una fuente de vibración de cuerpo entero perceptible por el trabajador/a? Se presenta en cercanía de máquinas donde se percibe la vibración, superficies vibrantes donde se está de pie o sentado como en maquinaria pesada y de conducción sentados o de pie. | K13: ¿Están los trabajadores/as en contacto con una fuente de vibración del segmento mano - brazo? Y ¿esta condición es frecuente o inherente a la tarea realizada?. Se presenta en situaciones de manejo de herramientas neumáticas o eléctricas, atornilladores o destornilladores neumáticos o eléctricos, uso de herramientas con impacto como martillos, cinceles, herramientas percutoras como taladros o grandes percutores
B14: 1 | C14: =Hoja1!C5 -> Seleccionadora línea cítricos 1 | D14: =Hoja1!E5 -> Empacado | E14: SI | F14: NO | G14: NO | H14: NO | I14: NO | J14: NO | K14: NO | L14: =IF(AND(E14="NO",F14="NO",G14="NO",H14="NO",I14="NO",J14="NO",K14="NO"),"Ausencia total del riesgo, reevaluar cada 3 años con nueva identificación inicial","Aplicar identificación avanzada-condición aceptable para cada tipo de factor de riesgo identificado") -> Aplicar identificación avanzada-condición aceptable para cada tipo de factor de riesgo identificado
B15: 2 | C15: =Hoja1!C6 -> Operador excavadora | D15: =Hoja1!E6 -> carga de camión | E15: SI | F15: NO | G15: NO | H15: NO | I15: SI | J15: SI | K15: SI | L15: =IF(AND(E15="NO",F15="NO",G15="NO",H15="NO",I15="NO",J15="NO",K15="NO"),"Ausencia total del riesgo, reevaluar cada 3 años con nueva identificación inicial","Aplicar identificación avanzada-condición aceptable para cada tipo de factor de riesgo identificado") -> Aplicar identificación avanzada-condición aceptable para cada tipo de factor de riesgo identificado
B16: 3 | C16: =Hoja1!C7 -> puesto 3 | D16: =Hoja1!E7 -> tarea 3 | E16: SI | F16: SI | G16: SI | H16: SI | I16: SI | J16: SI | K16: SI | L16: =IF(AND(E16="NO",F16="NO",G16="NO",H16="NO",I16="NO",J16="NO",K16="NO"),"Ausencia total del riesgo, reevaluar cada 3 años con nueva identificación inicial","Aplicar identificación avanzada-condición aceptable para cada tipo de factor de riesgo identificado") -> Aplicar identificación avanzada-condición aceptable para cada tipo de factor de riesgo identificado
B17: 4 | C17: =Hoja1!C8 -> puesto 4 | D17: =Hoja1!E8 -> tarea 4 | E17: SI | F17: SI | G17: SI | H17: SI | I17: SI | J17: SI | K17: SI | L17: =IF(AND(E17="NO",F17="NO",G17="NO",H17="NO",I17="NO",J17="NO",K17="NO"),"Ausencia total del riesgo, reevaluar cada 3 años con nueva identificación inicial","Aplicar identificación avanzada-condición aceptable para cada tipo de factor de riesgo identificado") -> Aplicar identificación avanzada-condición aceptable para cada tipo de factor de riesgo identificado
B18: 6 | C18: =Hoja1!C9 -> puesto 5 | D18: =Hoja1!E9 -> tarea 5 | E18: SI | F18: SI | G18: SI | H18: SI | I18: SI | J18: SI | K18: SI | L18: =IF(AND(E18="NO",F18="NO",G18="NO",H18="NO",I18="NO",J18="NO",K18="NO"),"Ausencia total del riesgo, reevaluar cada 3 años con nueva identificación inicial","Aplicar identificación avanzada-condición aceptable para cada tipo de factor de riesgo identificado") -> Aplicar identificación avanzada-condición aceptable para cada tipo de factor de riesgo identificado
B19: 7 | C19: =Hoja1!C10 -> puesto 6 | D19: =Hoja1!E10 -> tarea 6 | E19: SI | F19: SI | G19: SI | H19: SI | I19: SI | J19: SI | K19: SI | L19: =IF(AND(E19="NO",F19="NO",G19="NO",H19="NO",I19="NO",J19="NO",K19="NO"),"Ausencia total del riesgo, reevaluar cada 3 años con nueva identificación inicial","Aplicar identificación avanzada-condición aceptable para cada tipo de factor de riesgo identificado") -> Aplicar identificación avanzada-condición aceptable para cada tipo de factor de riesgo identificado
B20: 8 | C20: =Hoja1!C11 -> puesto 7 | D20: =Hoja1!E11 -> tarea 7 | E20: SI | F20: SI | G20: SI | H20: SI | I20: SI | J20: SI | K20: SI | L20: =IF(AND(E20="NO",F20="NO",G20="NO",H20="NO",I20="NO",J20="NO",K20="NO"),"Ausencia total del riesgo, reevaluar cada 3 años con nueva identificación inicial","Aplicar identificación avanzada-condición aceptable para cada tipo de factor de riesgo identificado") -> Aplicar identificación avanzada-condición aceptable para cada tipo de factor de riesgo identificado
B21: 9 | C21: =Hoja1!C12 -> puesto 8 | D21: =Hoja1!E12 -> tarea 8 | E21: SI | F21: SI | G21: SI | H21: SI | I21: SI | J21: SI | K21: SI | L21: =IF(AND(E21="NO",F21="NO",G21="NO",H21="NO",I21="NO",J21="NO",K21="NO"),"Ausencia total del riesgo, reevaluar cada 3 años con nueva identificación inicial","Aplicar identificación avanzada-condición aceptable para cada tipo de factor de riesgo identificado") -> Aplicar identificación avanzada-condición aceptable para cada tipo de factor de riesgo identificado
B22: 10 | C22: =Hoja1!C13 -> puesto 9 | D22: =Hoja1!E13 -> tarea 9 | E22: SI | F22: SI | G22: SI | H22: SI | I22: SI | J22: SI | K22: SI | L22: =IF(AND(E22="NO",F22="NO",G22="NO",H22="NO",I22="NO",J22="NO",K22="NO"),"Ausencia total del riesgo, reevaluar cada 3 años con nueva identificación inicial","Aplicar identificación avanzada-condición aceptable para cada tipo de factor de riesgo identificado") -> Aplicar identificación avanzada-condición aceptable para cada tipo de factor de riesgo identificado
B23: 11 | C23: =Hoja1!C14 -> puesto 10 | D23: =Hoja1!E14 -> tarea 10 | E23: SI | F23: SI | G23: SI | H23: SI | I23: SI | J23: SI | K23: SI | L23: =IF(AND(E23="NO",F23="NO",G23="NO",H23="NO",I23="NO",J23="NO",K23="NO"),"Ausencia total del riesgo, reevaluar cada 3 años con nueva identificación inicial","Aplicar identificación avanzada-condición aceptable para cada tipo de factor de riesgo identificado") -> Aplicar identificación avanzada-condición aceptable para cada tipo de factor de riesgo identificado
B24: 12 | C24: =Hoja1!C15 -> puesto 11 | D24: =Hoja1!E15 -> tarea 11 | E24: SI | F24: SI | G24: SI | H24: SI | I24: SI | J24: SI | K24: SI | L24: =IF(AND(E24="NO",F24="NO",G24="NO",H24="NO",I24="NO",J24="NO",K24="NO"),"Ausencia total del riesgo, reevaluar cada 3 años con nueva identificación inicial","Aplicar identificación avanzada-condición aceptable para cada tipo de factor de riesgo identificado") -> Aplicar identificación avanzada-condición aceptable para cada tipo de factor de riesgo identificado
B25: 13 | C25: =Hoja1!C16 -> puesto 12 | D25: =Hoja1!E16 -> tarea 12 | E25: SI | F25: SI | G25: SI | H25: SI | I25: SI | J25: SI | K25: SI | L25: =IF(AND(E25="NO",F25="NO",G25="NO",H25="NO",I25="NO",J25="NO",K25="NO"),"Ausencia total del riesgo, reevaluar cada 3 años con nueva identificación inicial","Aplicar identificación avanzada-condición aceptable para cada tipo de factor de riesgo identificado") -> Aplicar identificación avanzada-condición aceptable para cada tipo de factor de riesgo identificado
... B212: 200 | C212: =Hoja1!C203 -> puesto 199 | D212: =Hoja1!E203 -> 0 | E212: SI | F212: SI | G212: SI | H212: SI | I212: SI | J212: SI | K212: SI | L212: =IF(AND(E212="NO",F212="NO",G212="NO",H212="NO",I212="NO",J212="NO",K212="NO"),"Ausencia total del riesgo, reevaluar cada 3 años con nueva identificación inicial","Aplicar identificación avanzada-condición aceptable para cada tipo de factor de riesgo identificado") -> Aplicar identificación avanzada-condición aceptable para cada tipo de factor de riesgo identificado

Sheet Hoja1
O1: 4.-Trabajo repetitivo de miembros superiores. | W1: 5.-Postura de trabajo estática | AE1: 6.-Manipulación manual de cargas | AM1: 7.-Manipulación manual de cargas | AU1: 8.-Manejo manual de pacientes | BC1: 9.-Vibración de cuerpo completo | BK1: 10.-Vibración segmento mano – brazo
G2: Trabajo repetitivo de miembros superiores. | H2: Postura de trabajo estática | I2: Manipulación manual de cargas | J2: Manipulación manual de cargas | K2: Manejo manual de pacientes / personas | L2: Vibración de cuerpo completo | M2: Vibración segmento mano – brazo
A3: N° | B3: {='2'!C12:C13} -> Área de trabajo | C3: ='2'!D12 -> Puesto de trabajo | D3: {='2'!D12:D13} -> Puesto de trabajo | E3: {='2'!E12:E13} -> Tareas del puesto de trabajo | F3: {='3'!L12:L13} -> Resultado identificación inicial | G3: ¿Existe una o más tareas donde utilice las manos y miembros superiores con una duración total de una hora o más durante la jornada laboral y con un tiempo total de 5 o más horas a la semana? Donde tenga que movilizar, levantar, empujar, encajar, sostener, posicionar, armar, limpiar, apretar, lanzar, cortar, presionar, desarmar, atornillar, desatornillar, digitar con presión, comprimir, ubicar, moldear, traccionar. | H3: ¿Existen posturas de trabajo estáticas de cabeza/cuello, tronco y/o miembros superiores e inferiores, mantenidas por más de 4 segundos consecutivamente? Donde se observe estar sentado, cabeza inclinada hacia adelante o atrás, mirada situada en planos bajo nivel medio de tórax o pecho, cabeza rotada permanentemente hacia algún lado, mirada situada en planos sobre el nivel de cabeza, hombros situados por delante de las caderas de manera continua, tronco rotado o inclinado para sostener o movilizar objetos. | I3: Para el Levantamiento/Descenso/Transporte: ¿Existe levantamiento, descenso o transporte manual de un objeto de 3kg o más? Se observa que levanta, sostiene, trasporta, desplaza, moviliza, ubica con precisión ordenando, empuja, arrastra o tracciona, apila, paletiza. | J3: Tracción/Empuje ¿Existe empuje o arrastre de una carga utilizando el cuerpo completo con 1 o 2 manos? Se observa el empuje y/o arrastre de diferentes maneras carros, plataformas con rueda, superficies deslizantes, detención de objetos en movimiento, camillas, camas, sillas de rueda, paletizadores, grúas de uso manual mecanizadas, formas de tracción y empuje hechizas, carretillas. No se considera empuje y arrastre carros motorizados y controlados manualmente (conducción) | K3: ¿Se realiza alguna actividad que requiere fuerza para empujar, tirar, levantar, descender, transferir o de alguna manera mover o sostener una persona o parte del cuerpo de una persona? *NOTA: La condición a identificar debe incluir la actividad de manipulación, ya sea que se realice con o sin dispositivos de asistencia. Esta condición está determinada por el riesgo asociado a las características de la carga humana que requiere control sensible de la masa corporal por parte del operador. | L3: ¿Están los trabajadores/as expuestos/as a vibraciones por una fuente de vibración de cuerpo entero perceptible por el trabajador/a? Se presenta en cercanía de máquinas donde se percibe la vibración, superficies vibrantes donde se está de pie o sentado como en maquinaria pesada y de conducción sentados o de pie. | M3: ¿Están los trabajadores/as en contacto con una fuente de vibración del segmento mano - brazo? Y ¿esta condición es frecuente o inherente a la tarea realizada?. Se presenta en situaciones de manejo de herramientas neumáticas o eléctricas, atornilladores o destornilladores neumáticos o eléctricos, uso de herramientas con impacto como martillos, cinceles, herramientas percutoras como taladros o grandes percutores | N3: {='3'!L12:L13} -> Resultado identificación inicial | O3: Área de trabajo | P3: Puesto de trabajo | Q3: Tareas del puesto de trabajo | R3: Horario de funcionamiento | S3: Horas extras | U3: N° Trabajadores Expuestos | W3: Área de trabajo | X3: Puesto de trabajo | Y3: Tareas del puesto de trabajo | Z3: Horario de funcionamiento | AA3: Horas extras | AC3: N° Trabajadores Expuestos | AE3: Área de trabajo | AF3: Puesto de trabajo | AG3: Tareas del puesto de trabajo | AH3: Horario de funcionamiento | AI3: Horas extras | AK3: N° Trabajadores Expuestos | AM3: Área de trabajo | AN3: Puesto de trabajo | AO3: Tareas del puesto de trabajo | AP3: Horario de funcionamiento | AQ3: Horas extras | AS3: N° Trabajadores Expuestos | AU3: Área de trabajo | AV3: Puesto de trabajo | AW3: Tareas del puesto de trabajo | AX3: Horario de funcionamiento | AY3: Horas extras | BA3: N° Trabajadores Expuestos | BC3: Área de trabajo | BD3: Puesto de trabajo | BE3: Tareas del puesto de trabajo | BF3: Horario de funcionamiento | BG3: Horas extras | BI3: N° Trabajadores Expuestos | BK3: Área de trabajo | BL3: Puesto de trabajo | BM3: Tareas del puesto de trabajo | BN3: Horario de funcionamiento | BO3: Horas extras | BQ3: N° Trabajadores Expuestos
B4: 0 | D4: 0 | E4: 0 | F4: 0 | N4: 0 | S4: Por dia | T4: Por semana | U4: Hombre | V4: Mujer | AA4: Por dia | AB4: Por semana | AC4: Hombre | AD4: Mujer | AI4: Por dia | AJ4: Por semana | AK4: Hombre | AL4: Mujer | AQ4: Por dia | AR4: Por semana | AS4: Hombre | AT4: Mujer | AY4: Por dia | AZ4: Por semana | BA4: Hombre | BB4: Mujer | BG4: Por dia | BH4: Por semana | BI4: Hombre | BJ4: Mujer | BO4: Por dia | BP4: Por semana | BQ4: Hombre | BR4: Mujer
A5: 1 | B5: ='2'!C14 -> Packing | C5: ='2'!D14 -> Seleccionadora línea cítricos 1 | D5: {=_xlfn.UNIQUE(C5:C203)} -> Seleccionadora línea cítricos 1 | E5: ='2'!E14 -> Empacado | F5: ='3'!L14 -> Aplicar identificación avanzada-condición aceptable para cada tipo de factor de riesgo identificado | G5: ='3'!E14 -> SI | H5: ='3'!F14 -> NO | I5: ='3'!G14 -> NO | J5: ='3'!H14 -> NO | K5: ='3'!I14 -> NO | L5: ='3'!J14 -> NO | M5: ='3'!K14 -> NO | N5: ='3'!L14 -> Aplicar identificación avanzada-condición aceptable para cada tipo de factor de riesgo identificado | O5: =IF(AND(N5="Aplicar identificación avanzada-condición aceptable para cada tipo de factor de riesgo identificado",G5="SI"),VLOOKUP(A5,'2'!$B$12:$M$212,2,FALSE)," ") -> Packing | P5: =IF(AND(N5="Aplicar identificación avanzada-condición aceptable para cada tipo de factor de riesgo identificado",G5="SI"),VLOOKUP(A5,'2'!$B$12:$M$212,3,FALSE)," ") -> Seleccionadora línea cítricos 1 | Q5: =IF(AND(N5="Aplicar identificación avanzada-condición aceptable para cada tipo de factor de riesgo identificado",G5="SI"),VLOOKUP(A5,'2'!$B$12:$M$212,4,FALSE)," ") -> Empacado | R5: =IF(AND(N5="Aplicar identificación avanzada-condición aceptable para cada tipo de factor de riesgo identificado",G5="SI"),VLOOKUP(A5,'2'!$B$12:$M$212,6,FALSE)," ") -> 8:00 a 16:00 | S5: =IF(AND(N5="Aplicar identificación avanzada-condición aceptable para cada tipo de factor de riesgo identificado",G5="SI"),VLOOKUP(A5,'2'!$B$12:$M$212,7,FALSE)," ") -> 0 | T5: =IF(AND(N5="Aplicar identificación avanzada-condición aceptable para cada tipo de factor de riesgo identificado",G5="SI"),VLOOKUP(A5,'2'!$B$12:$M$212,8,FALSE)," ") -> 0 | U5: =IF(AND(N5="Aplicar identificación avanzada-condición aceptable para cada tipo de factor de riesgo identificado",G5="SI"),VLOOKUP(A5,'2'!$B$12:$M$212,9,FALSE)," ") -> 6 | V5: =IF(AND(N5="Aplicar identificación avanzada-condición aceptable para cada tipo de factor de riesgo identificado",G5="SI"),VLOOKUP(A5,'2'!$B$12:$M$212,10,FALSE)," ") -> 6 | W5: =IF(AND(N5="Aplicar identificación avanzada-condición aceptable para cada tipo de factor de riesgo identificado",H5="SI"),VLOOKUP(A5,'2'!$B$12:$M$212,2,FALSE)," ") | X5: =IF(AND(N5="Aplicar identificación avanzada-condición aceptable para cada tipo de factor de riesgo identificado",H5="SI"),VLOOKUP(A5,'2'!$B$12:$M$212,3,FALSE)," ") | Y5: =IF(AND(N5="Aplicar identificación avanzada-condición aceptable para cada tipo de factor de riesgo identificado",H5="SI"),VLOOKUP(A5,'2'!$B$12:$M$212,4,FALSE)," ") | Z5: =IF(AND(N5="Aplicar identificación avanzada-condición aceptable para cada tipo de factor de riesgo identificado",H5="SI"),VLOOKUP(A5,'2'!$B$12:$M$212,6,FALSE)," ") | AA5: =IF(AND(N5="Aplicar identificación avanzada-condición aceptable para cada tipo de factor de riesgo identificado",H5="SI"),VLOOKUP(A5,'2'!$B$12:$M$212,7,FALSE)," ") | AB5: =IF(AND(N5="Aplicar identificación avanzada-condición aceptable para cada tipo de factor de riesgo identificado",H5="SI"),VLOOKUP(A5,'2'!$B$12:$M$212,8,FALSE)," ") | AC5: =IF(AND(N5="Aplicar identificación avanzada-condición aceptable para cada tipo de factor de riesgo identificado",H5="SI"),VLOOKUP(A5,'2'!$B$12:$M$212,9,FALSE)," ") | AD5: =IF(AND(N5="Aplicar identificación avanzada-condición aceptable para cada tipo de factor de riesgo identificado",H5="SI"),VLOOKUP(A5,'2'!$B$12:$M$212,10,FALSE)," ") | AE5: =IF(AND(N5="Aplicar identificación avanzada-condición aceptable para cada tipo de factor de riesgo identificado",I5="SI"),VLOOKUP(A5,'2'!$B$12:$M$212,2,FALSE)," ") | AF5: =IF(AND(N5="Aplicar identificación avanzada-condición aceptable para cada tipo de factor de riesgo identificado",I5="SI"),VLOOKUP(A5,'2'!$B$12:$M$212,3,FALSE)," ") | AG5: =IF(AND(N5="Aplicar identificación avanzada-condición aceptable para cada tipo de factor de riesgo identificado",I5="SI"),VLOOKUP(A5,'2'!$B$12:$M$212,4,FALSE)," ") | AH5: =IF(AND(N5="Aplicar identificación avanzada-condición aceptable para cada tipo de factor de riesgo identificado",I5="SI"),VLOOKUP(A5,'2'!$B$12:$M$212,6,FALSE)," ") | AI5: =IF(AND(N5="Aplicar identificación avanzada-condición aceptable para cada tipo de factor de riesgo identificado",I5="SI"),VLOOKUP(A5,'2'!$B$12:$M$212,7,FALSE)," ") | AJ5: =IF(AND(N5="Aplicar identificación avanzada-condición aceptable para cada tipo de factor de riesgo identificado",I5="SI"),VLOOKUP(A5,'2'!$B$12:$M$212,8,FALSE)," ") | AK5: =IF(AND(N5="Aplicar identificación avanzada-condición aceptable para cada tipo de factor de riesgo identificado",I5="SI"),VLOOKUP(A5,'2'!$B$12:$M$212,9,FALSE)," ") | AL5: =IF(AND(N5="Aplicar identificación avanzada-condición aceptable para cada tipo de factor de riesgo identificado",I5="SI"),VLOOKUP(A5,'2'!$B$12:$M$212,10,FALSE)," ") | AM5: =IF(AND(N5="Aplicar identificación avanzada-condición aceptable para cada tipo de factor de riesgo identificado",J5="SI"),VLOOKUP(A5,'2'!$B$12:$M$212,2,FALSE)," ") | AN5: =IF(AND(N5="Aplicar identificación avanzada-condición aceptable para cada tipo de factor de riesgo identificado",J5="SI"),VLOOKUP(A5,'2'!$B$12:$M$212,3,FALSE)," ") | AO5: =IF(AND(N5="Aplicar identificación avanzada-condición aceptable para cada tipo de factor de riesgo identificado",J5="SI"),VLOOKUP(A5,'2'!$B$12:$M$212,4,FALSE)," ") | AP5: =IF(AND(N5="Aplicar identificación avanzada-condición aceptable para cada tipo de factor de riesgo identificado",J5="SI"),VLOOKUP(A5,'2'!$B$12:$M$212,6,FALSE)," ") | AQ5: =IF(AND(N5="Aplicar identificación avanzada-condición aceptable para cada tipo de factor de riesgo identificado",J5="SI"),VLOOKUP(A5,'2'!$B$12:$M$212,7,FALSE)," ") | AR5: =IF(AND(N5="Aplicar identificación avanzada-condición aceptable para cada tipo de factor de riesgo identificado",J5="SI"),VLOOKUP(A5,'2'!$B$12:$M$212,8,FALSE)," ") | AS5: =IF(AND(N5="Aplicar identificación avanzada-condición aceptable para cada tipo de factor de riesgo identificado",J5="SI"),VLOOKUP(A5,'2'!$B$12:$M$212,9,FALSE)," ") | AT5: =IF(AND(N5="Aplicar identificación avanzada-condición aceptable para cada tipo de factor de riesgo identificado",J5="SI"),VLOOKUP(A5,'2'!$B$12:$M$212,10,FALSE)," ") | AU5: =IF(AND(N5="Aplicar identificación avanzada-condición aceptable para cada tipo de factor de riesgo identificado",K5="SI"),VLOOKUP(A5,'2'!$B$12:$M$212,2,FALSE)," ") | AV5: =IF(AND(N5="Aplicar identificación avanzada-condición aceptable para cada tipo de factor de riesgo identificado",K5="SI"),VLOOKUP(A5,'2'!$B$12:$M$212,3,FALSE)," ") | AW5: =IF(AND(N5="Aplicar identificación avanzada-condición aceptable para cada tipo de factor de riesgo identificado",K5="SI"),VLOOKUP(A5,'2'!$B$12:$M$212,4,FALSE)," ") | AX5: =IF(AND(N5="Aplicar identificación avanzada-condición aceptable para cada tipo de factor de riesgo identificado",K5="SI"),VLOOKUP(A5,'2'!$B$12:$M$212,6,FALSE)," ") | AY5: =IF(AND(N5="Aplicar identificación avanzada-condición aceptable para cada tipo de factor de riesgo identificado",K5="SI"),VLOOKUP(A5,'2'!$B$12:$M$212,7,FALSE)," ") | AZ5: =IF(AND(N5="Aplicar identificación avanzada-condición aceptable para cada tipo de factor de riesgo identificado",K5="SI"),VLOOKUP(A5,'2'!$B$12:$M$212,8,FALSE)," ") | BA5: =IF(AND(N5="Aplicar identificación avanzada-condición aceptable para cada tipo de factor de riesgo identificado",K5="SI"),VLOOKUP(A5,'2'!$B$12:$M$212,9,FALSE)," ") | BB5: =IF(AND(N5="Aplicar identificación avanzada-condición aceptable para cada tipo de factor de riesgo identificado",K5="SI"),VLOOKUP(A5,'2'!$B$12:$M$212,10,FALSE)," ") | BC5: =IF(AND(N5="Aplicar identificación avanzada-condición aceptable para cada tipo de factor de riesgo identificado",L5="SI"),VLOOKUP(A5,'2'!$B$12:$M$212,2,FALSE)," ") | BD5: =IF(AND(N5="Aplicar identificación avanzada-condición aceptable para cada tipo de factor de riesgo identificado",L5="SI"),VLOOKUP(A5,'2'!$B$12:$M$212,3,FALSE)," ") | BE5: =IF(AND(N5="Aplicar identificación avanzada-condición aceptable para cada tipo de factor de riesgo identificado",L5="SI"),VLOOKUP(A5,'2'!$B$12:$M$212,4,FALSE)," ") | BF5: =IF(AND(N5="Aplicar identificación avanzada-condición aceptable para cada tipo de factor de riesgo identificado",L5="SI"),VLOOKUP(A5,'2'!$B$12:$M$212,6,FALSE)," ") | BG5: =IF(AND(N5="Aplicar identificación avanzada-condición aceptable para cada tipo de factor de riesgo identificado",L5="SI"),VLOOKUP(A5,'2'!$B$12:$M$212,7,FALSE)," ") | BH5: =IF(AND(N5="Aplicar identificación avanzada-condición aceptable para cada tipo de factor de riesgo identificado",L5="SI"),VLOOKUP(A5,'2'!$B$12:$M$212,8,FALSE)," ") | BI5: =IF(AND(N5="Aplicar identificación avanzada-condición aceptable para cada tipo de factor de riesgo identificado",L5="SI"),VLOOKUP(A5,'2'!$B$12:$M$212,9,FALSE)," ") | BJ5: =IF(AND(N5="Aplicar identificación avanzada-condición aceptable para cada tipo de factor de riesgo identificado",L5="SI"),VLOOKUP(A5,'2'!$B$12:$M$212,10,FALSE)," ") | BK5: =IF(AND(N5="Aplicar identificación avanzada-condición aceptable para cada tipo de factor de riesgo identificado",M5="SI"),VLOOKUP(A5,'2'!$B$12:$M$212,2,FALSE)," ") | BL5: =IF(AND(N5="Aplicar identificación avanzada-condición aceptable para cada tipo de factor de riesgo identificado",M5="SI"),VLOOKUP(A5,'2'!$B$12:$M$212,3,FALSE)," ") | BM5: =IF(AND(N5="Aplicar identificación avanzada-condición aceptable para cada tipo de factor de riesgo identificado",M5="SI"),VLOOKUP(A5,'2'!$B$12:$M$212,4,FALSE)," ") | BN5: =IF(AND(N5="Aplicar identificación avanzada-condición aceptable para cada tipo de factor de riesgo identificado",M5="SI"),VLOOKUP(A5,'2'!$B$12:$M$212,6,FALSE)," ") | BO5: =IF(AND(N5="Aplicar identificación avanzada-condición aceptable para cada tipo de factor de riesgo identificado",M5="SI"),VLOOKUP(A5,'2'!$B$12:$M$212,7,FALSE)," ") | BP5: =IF(AND(N5="Aplicar identificación avanzada-condición aceptable para cada tipo de factor de riesgo identificado",M5="SI"),VLOOKUP(A5,'2'!$B$12:$M$212,8,FALSE)," ") | BQ5: =IF(AND(N5="Aplicar identificación avanzada-condición aceptable para cada tipo de factor de riesgo identificado",M5="SI"),VLOOKUP(A5,'2'!$B$12:$M$212,9,FALSE)," ") | BR5: =IF(AND(N5="Aplicar identificación avanzada-condición aceptable para cada tipo de factor de riesgo identificado",M5="SI"),VLOOKUP(A5,'2'!$B$12:$M$212,10,FALSE)," ")
A6: 2 | B6: ='2'!C15 -> Faena | C6: ='2'!D15 -> Operador excavadora | D6: Operador excavadora | E6: ='2'!E15 -> carga de camión | F6: ='3'!L15 -> Aplicar identificación avanzada-condición aceptable para cada tipo de factor de riesgo identificado | G6: ='3'!E15 -> SI | H6: ='3'!F15 -> NO | I6: ='3'!G15 -> NO | J6: ='3'!H15 -> NO | K6: ='3'!I15 -> SI | L6: ='3'!J15 -> SI | M6: ='3'!K15 -> SI | N6: ='3'!L15 -> Aplicar identificación avanzada-condición aceptable para cada tipo de factor de riesgo identificado | O6: =IF(AND(N6="Aplicar identificación avanzada-condición aceptable para cada tipo de factor de riesgo identificado",G6="SI"),VLOOKUP(A6,'2'!$B$12:$M$212,2,FALSE)," ") -> Faena | P6: =IF(AND(N6="Aplicar identificación avanzada-condición aceptable para cada tipo de factor de riesgo identificado",G6="SI"),VLOOKUP(A6,'2'!$B$12:$M$212,3,FALSE)," ") -> Operador excavadora | Q6: =IF(AND(N6="Aplicar identificación avanzada-condición aceptable para cada tipo de factor de riesgo identificado",G6="SI"),VLOOKUP(A6,'2'!$B$12:$M$212,4,FALSE)," ") -> carga de camión | R6: =IF(AND(N6="Aplicar identificación avanzada-condición aceptable para cada tipo de factor de riesgo identificado",G6="SI"),VLOOKUP(A6,'2'!$B$12:$M$212,6,FALSE)," ") -> 8:00 a 18:00 | S6: =IF(AND(N6="Aplicar identificación avanzada-condición aceptable para cada tipo de factor de riesgo identificado",G6="SI"),VLOOKUP(A6,'2'!$B$12:$M$212,7,FALSE)," ") -> 2 | T6: =IF(AND(N6="Aplicar identificación avanzada-condición aceptable para cada tipo de factor de riesgo identificado",G6="SI"),VLOOKUP(A6,'2'!$B$12:$M$212,8,FALSE)," ") -> 10 | U6: =IF(AND(N6="Aplicar identificación avanzada-condición aceptable para cada tipo de factor de riesgo identificado",G6="SI"),VLOOKUP(A6,'2'!$B$12:$M$212,9,FALSE)," ") -> 1 | V6: =IF(AND(N6="Aplicar identificación avanzada-condición aceptable para cada tipo de factor de riesgo identificado",G6="SI"),VLOOKUP(A6,'2'!$B$12:$M$212,10,FALSE)," ") -> 0 | W6: =IF(AND(N6="Aplicar identificación avanzada-condición aceptable para cada tipo de factor de riesgo identificado",H6="SI"),VLOOKUP(A6,'2'!$B$12:$M$212,2,FALSE)," ") | X6: =IF(AND(N6="Aplicar identificación avanzada-condición aceptable para cada tipo de factor de riesgo identificado",H6="SI"),VLOOKUP(A6,'2'!$B$12:$M$212,3,FALSE)," ") | Y6: =IF(AND(N6="Aplicar identificación avanzada-condición aceptable para cada tipo de factor de riesgo identificado",H6="SI"),VLOOKUP(A6,'2'!$B$12:$M$212,4,FALSE)," ") | Z6: =IF(AND(N6="Aplicar identificación avanzada-condición aceptable para cada tipo de factor de riesgo identificado",H6="SI"),VLOOKUP(A6,'2'!$B$12:$M$212,4,FALSE)," ") | AA6: =IF(AND(N6="Aplicar identificación avanzada-condición aceptable para cada tipo de factor de riesgo identificado",H6="SI"),VLOOKUP(A6,'2'!$B$12:$M$212,7,FALSE)," ") | AB6: =IF(AND(N6="Aplicar identificación avanzada-condición aceptable para cada tipo de factor de riesgo identificado",H6="SI"),VLOOKUP(A6,'2'!$B$12:$M$212,8,FALSE)," ") | AC6: =IF(AND(N6="Aplicar identificación avanzada-condición aceptable para cada tipo de factor de riesgo identificado",H6="SI"),VLOOKUP(A6,'2'!$B$12:$M$212,9,FALSE)," ") | AD6: =IF(AND(N6="Aplicar identificación avanzada-condición aceptable para cada tipo de factor de riesgo identificado",H6="SI"),VLOOKUP(A6,'2'!$B$12:$M$212,10,FALSE)," ") | AE6: =IF(AND(N6="Aplicar identificación avanzada-condición aceptable para cada tipo de factor de riesgo identificado",I6="SI"),VLOOKUP(A6,'2'!$B$12:$M$212,2,FALSE)," ") | AF6: =IF(AND(N6="Aplicar identificación avanzada-condición aceptable para cada tipo de factor de riesgo identificado",I6="SI"),VLOOKUP(A6,'2'!$B$12:$M$212,3,FALSE)," ") | AG6: =IF(AND(N6="Aplicar identificación avanzada-condición aceptable para cada tipo de factor de riesgo identificado",I6="SI"),VLOOKUP(A6,'2'!$B$12:$M$212,4,FALSE)," ") | AH6: =IF(AND(N6="Aplicar identificación avanzada-condición aceptable para cada tipo de factor de riesgo identificado",I6="SI"),VLOOKUP(A6,'2'!$B$12:$M$212,6,FALSE)," ") | AI6: =IF(AND(N6="Aplicar identificación avanzada-condición aceptable para cada tipo de factor de riesgo identificado",I6="SI"),VLOOKUP(A6,'2'!$B$12:$M$212,7,FALSE)," ") | AJ6: =IF(AND(N6="Aplicar identificación avanzada-condición aceptable para cada tipo de factor de riesgo identificado",I6="SI"),VLOOKUP(A6,'2'!$B$12:$M$212,8,FALSE)," ") | AK6: =IF(AND(N6="Aplicar identificación avanzada-condición aceptable para cada tipo de factor de riesgo identificado",I6="SI"),VLOOKUP(A6,'2'!$B$12:$M$212,9,FALSE)," ") | AL6: =IF(AND(N6="Aplicar identificación avanzada-condición aceptable para cada tipo de factor de riesgo identificado",I6="SI"),VLOOKUP(A6,'2'!$B$12:$M$212,10,FALSE)," ") | AM6: =IF(AND(N6="Aplicar identificación avanzada-condición aceptable para cada tipo de factor de riesgo identificado",J6="SI"),VLOOKUP(A6,'2'!$B$12:$M$212,2,FALSE)," ") | AN6: =IF(AND(N6="Aplicar identificación avanzada-condición aceptable para cada tipo de factor de riesgo identificado",J6="SI"),VLOOKUP(A6,'2'!$B$12:$M$212,3,FALSE)," ") | AO6: =IF(AND(N6="Aplicar identificación avanzada-condición aceptable para cada tipo de factor de riesgo identificado",J6="SI"),VLOOKUP(A6,'2'!$B$12:$M$212,4,FALSE)," ") | AP6: =IF(AND(N6="Aplicar identificación avanzada-condición aceptable para cada tipo de factor de riesgo identificado",J6="SI"),VLOOKUP(A6,'2'!$B$12:$M$212,6,FALSE)," ") | AQ6: =IF(AND(N6="Aplicar identificación avanzada-condición aceptable para cada tipo de factor de riesgo identificado",J6="SI"),VLOOKUP(A6,'2'!$B$12:$M$212,7,FALSE)," ") | AR6: =IF(AND(N6="Aplicar identificación avanzada-condición aceptable para cada tipo de factor de riesgo identificado",J6="SI"),VLOOKUP(A6,'2'!$B$12:$M$212,8,FALSE)," ") | AS6: =IF(AND(N6="Aplicar identificación avanzada-condición aceptable para cada tipo de factor de riesgo identificado",J6="SI"),VLOOKUP(A6,'2'!$B$12:$M$212,9,FALSE)," ") | AT6: =IF(AND(N6="Aplicar identificación avanzada-condición aceptable para cada tipo de factor de riesgo identificado",J6="SI"),VLOOKUP(A6,'2'!$B$12:$M$212,10,FALSE)," ") | AU6: =IF(AND(N6="Aplicar identificación avanzada-condición aceptable para cada tipo de factor de riesgo identificado",K6="SI"),VLOOKUP(A6,'2'!$B$12:$M$212,2,FALSE)," ") -> Faena | AV6: =IF(AND(N6="Aplicar identificación avanzada-condición aceptable para cada tipo de factor de riesgo identificado",K6="SI"),VLOOKUP(A6,'2'!$B$12:$M$212,3,FALSE)," ") -> Operador excavadora | AW6: =IF(AND(N6="Aplicar identificación avanzada-condición aceptable para cada tipo de factor de riesgo identificado",K6="SI"),VLOOKUP(A6,'2'!$B$12:$M$212,4,FALSE)," ") -> carga de camión | AX6: =IF(AND(N6="Aplicar identificación avanzada-condición aceptable para cada tipo de factor de riesgo identificado",K6="SI"),VLOOKUP(A6,'2'!$B$12:$M$212,6,FALSE)," ") -> 8:00 a 18:00 | AY6: =IF(AND(N6="Aplicar identificación avanzada-condición aceptable para cada tipo de factor de riesgo identificado",K6="SI"),VLOOKUP(A6,'2'!$B$12:$M$212,7,FALSE)," ") -> 2 | AZ6: =IF(AND(N6="Aplicar identificación avanzada-condición aceptable para cada tipo de factor de riesgo identificado",K6="SI"),VLOOKUP(A6,'2'!$B$12:$M$212,8,FALSE)," ") -> 10 | BA6: =IF(AND(N6="Aplicar identificación avanzada-condición aceptable para cada tipo de factor de riesgo identificado",K6="SI"),VLOOKUP(A6,'2'!$B$12:$M$212,9,FALSE)," ") -> 1 | BB6: =IF(AND(N6="Aplicar identificación avanzada-condición aceptable para cada tipo de factor de riesgo identificado",K6="SI"),VLOOKUP(A6,'2'!$B$12:$M$212,10,FALSE)," ") -> 0 | BC6: =IF(AND(N6="Aplicar identificación avanzada-condición aceptable para cada tipo de factor de riesgo identificado",L6="SI"),VLOOKUP(A6,'2'!$B$12:$M$212,2,FALSE)," ") -> Faena | BD6: =IF(AND(N6="Aplicar identificación avanzada-condición aceptable para cada tipo de factor de riesgo identificado",L6="SI"),VLOOKUP(A6,'2'!$B$12:$M$212,3,FALSE)," ") -> Operador excavadora | BE6: =IF(AND(N6="Aplicar identificación avanzada-condición aceptable para cada tipo de factor de riesgo identificado",L6="SI"),VLOOKUP(A6,'2'!$B$12:$M$212,4,FALSE)," ") -> carga de camión | BF6: =IF(AND(N6="Aplicar identificación avanzada-condición aceptable para cada tipo de factor de riesgo identificado",L6="SI"),VLOOKUP(A6,'2'!$B$12:$M$212,6,FALSE)," ") -> 8:00 a 18:00 | BG6: =IF(AND(N6="Aplicar identificación avanzada-condición aceptable para cada tipo de factor de riesgo identificado",L6="SI"),VLOOKUP(A6,'2'!$B$12:$M$212,7,FALSE)," ") -> 2 | BH6: =IF(AND(N6="Aplicar identificación avanzada-condición aceptable para cada tipo de factor de riesgo identificado",L6="SI"),VLOOKUP(A6,'2'!$B$12:$M$212,8,FALSE)," ") -> 10 | BI6: =IF(AND(N6="Aplicar identificación avanzada-condición aceptable para cada tipo de factor de riesgo identificado",L6="SI"),VLOOKUP(A6,'2'!$B$12:$M$212,9,FALSE)," ") -> 1 | BJ6: =IF(AND(N6="Aplicar identificación avanzada-condición aceptable para cada tipo de factor de riesgo identificado",L6="SI"),VLOOKUP(A6,'2'!$B$12:$M$212,10,FALSE)," ") -> 0 | BK6: =IF(AND(N6="Aplicar identificación avanzada-condición aceptable para cada tipo de factor de riesgo identificado",M6="SI"),VLOOKUP(A6,'2'!$B$12:$M$212,2,FALSE)," ") -> Faena | BL6: =IF(AND(N6="Aplicar identificación avanzada-condición aceptable para cada tipo de factor de riesgo identificado",M6="SI"),VLOOKUP(A6,'2'!$B$12:$M$212,3,FALSE)," ") -> Operador excavadora | BM6: =IF(AND(N6="Aplicar identificación avanzada-condición aceptable para cada tipo de factor de riesgo identificado",M6="SI"),VLOOKUP(A6,'2'!$B$12:$M$212,4,FALSE)," ") -> carga de camión | BN6: =IF(AND(N6="Aplicar identificación avanzada-condición aceptable para cada tipo de factor de riesgo identificado",M6="SI"),VLOOKUP(A6,'2'!$B$12:$M$212,6,FALSE)," ") -> 8:00 a 18:00 | BO6: =IF(AND(N6="Aplicar identificación avanzada-condición aceptable para cada tipo de factor de riesgo identificado",M6="SI"),VLOOKUP(A6,'2'!$B$12:$M$212,7,FALSE)," ") -> 2 | BP6: =IF(AND(N6="Aplicar identificación avanzada-condición aceptable para cada tipo de factor de riesgo identificado",M6="SI"),VLOOKUP(A6,'2'!$B$12:$M$212,8,FALSE)," ") -> 10 | BQ6: =IF(AND(N6="Aplicar identificación avanzada-condición aceptable para cada tipo de factor de riesgo identificado",M6="SI"),VLOOKUP(A6,'2'!$B$12:$M$212,9,FALSE)," ") -> 1 | BR6: =IF(AND(N6="Aplicar identificación avanzada-condición aceptable para cada tipo de factor de riesgo identificado",M6="SI"),VLOOKUP(A6,'2'!$B$12:$M$212,10,FALSE)," ") -> 0
A7: 3 | B7: ='2'!C16 -> area 3 | C7: ='2'!D16 -> puesto 3 | D7: puesto 3 | E7: ='2'!E16 -> tarea 3 | F7: ='3'!L16 -> Aplicar identificación avanzada-condición aceptable para cada tipo de factor de riesgo identificado | G7: ='3'!E16 -> SI | H7: ='3'!F16 -> SI | I7: ='3'!G16 -> SI | J7: ='3'!H16 -> SI | K7: ='3'!I16 -> SI | L7: ='3'!J16 -> SI | M7: ='3'!K16 -> SI | N7: ='3'!L16 -> Aplicar identificación avanzada-condición aceptable para cada tipo de factor de riesgo identificado | O7: =IF(AND(N7="Aplicar identificación avanzada-condición aceptable para cada tipo de factor de riesgo identificado",G7="SI"),VLOOKUP(A7,'2'!$B$12:$M$212,2,FALSE)," ") -> area 3 | P7: =IF(AND(N7="Aplicar identificación avanzada-condición aceptable para cada tipo de factor de riesgo identificado",G7="SI"),VLOOKUP(A7,'2'!$B$12:$M$212,3,FALSE)," ") -> puesto 3 | Q7: =IF(AND(N7="Aplicar identificación avanzada-condición aceptable para cada tipo de factor de riesgo identificado",G7="SI"),VLOOKUP(A7,'2'!$B$12:$M$212,4,FALSE)," ") -> tarea 3 | R7: =IF(AND(N7="Aplicar identificación avanzada-condición aceptable para cada tipo de factor de riesgo identificado",G7="SI"),VLOOKUP(A7,'2'!$B$12:$M$212,6,FALSE)," ") -> 0 | S7: =IF(AND(N7="Aplicar identificación avanzada-condición aceptable para cada tipo de factor de riesgo identificado",G7="SI"),VLOOKUP(A7,'2'!$B$12:$M$212,7,FALSE)," ") -> 0 | T7: =IF(AND(N7="Aplicar identificación avanzada-condición aceptable para cada tipo de factor de riesgo identificado",G7="SI"),VLOOKUP(A7,'2'!$B$12:$M$212,8,FALSE)," ") -> 0 | U7: =IF(AND(N7="Aplicar identificación avanzada-condición aceptable para cada tipo de factor de riesgo identificado",G7="SI"),VLOOKUP(A7,'2'!$B$12:$M$212,9,FALSE)," ") -> 0 | V7: =IF(AND(N7="Aplicar identificación avanzada-condición aceptable para cada tipo de factor de riesgo identificado",G7="SI"),VLOOKUP(A7,'2'!$B$12:$M$212,10,FALSE)," ") -> 0 | W7: =IF(AND(N7="Aplicar identificación avanzada-condición aceptable para cada tipo de factor de riesgo identificado",H7="SI"),VLOOKUP(A7,'2'!$B$12:$M$212,2,FALSE)," ") -> area 3 | X7: =IF(AND(N7="Aplicar identificación avanzada-condición aceptable para cada tipo de factor de riesgo identificado",H7="SI"),VLOOKUP(A7,'2'!$B$12:$M$212,3,FALSE)," ") -> puesto 3 | Y7: =IF(AND(N7="Aplicar identificación avanzada-condición aceptable para cada tipo de factor de riesgo identificado",H7="SI"),VLOOKUP(A7,'2'!$B$12:$M$212,4,FALSE)," ") -> tarea 3 | Z7: =IF(AND(N7="Aplicar identificación avanzada-condición aceptable para cada tipo de factor de riesgo identificado",H7="SI"),VLOOKUP(A7,'2'!$B$12:$M$212,4,FALSE)," ") -> tarea 3 | AA7: =IF(AND(N7="Aplicar identificación avanzada-condición aceptable para cada tipo de factor de riesgo identificado",H7="SI"),VLOOKUP(A7,'2'!$B$12:$M$212,7,FALSE)," ") -> 0 | AB7: =IF(AND(N7="Aplicar identificación avanzada-condición aceptable para cada tipo de factor de riesgo identificado",H7="SI"),VLOOKUP(A7,'2'!$B$12:$M$212,8,FALSE)," ") -> 0 | AC7: =IF(AND(N7="Aplicar identificación avanzada-condición aceptable para cada tipo de factor de riesgo identificado",H7="SI"),VLOOKUP(A7,'2'!$B$12:$M$212,9,FALSE)," ") -> 0 | AD7: =IF(AND(N7="Aplicar identificación avanzada-condición aceptable para cada tipo de factor de riesgo identificado",H7="SI"),VLOOKUP(A7,'2'!$B$12:$M$212,10,FALSE)," ") -> 0 | AE7: =IF(AND(N7="Aplicar identificación avanzada-condición aceptable para cada tipo de factor de riesgo identificado",I7="SI"),VLOOKUP(A7,'2'!$B$12:$M$212,2,FALSE)," ") -> area 3 | AF7: =IF(AND(N7="Aplicar identificación avanzada-condición aceptable para cada tipo de factor de riesgo identificado",I7="SI"),VLOOKUP(A7,'2'!$B$12:$M$212,3,FALSE)," ") -> puesto 3 | AG7: =IF(AND(N7="Aplicar identificación avanzada-condición aceptable para cada tipo de factor de riesgo identificado",I7="SI"),VLOOKUP(A7,'2'!$B$12:$M$212,4,FALSE)," ") -> tarea 3 | AH7: =IF(AND(N7="Aplicar identificación avanzada-condición aceptable para cada tipo de factor de riesgo identificado",I7="SI"),VLOOKUP(A7,'2'!$B$12:$M$212,6,FALSE)," ") -> 0 | AI7: =IF(AND(N7="Aplicar identificación avanzada-condición aceptable para cada tipo de factor de riesgo identificado",I7="SI"),VLOOKUP(A7,'2'!$B$12:$M$212,7,FALSE)," ") -> 0 | AJ7: =IF(AND(N7="Aplicar identificación avanzada-condición aceptable para cada tipo de factor de riesgo identificado",I7="SI"),VLOOKUP(A7,'2'!$B$12:$M$212,8,FALSE)," ") -> 0 | AK7: =IF(AND(N7="Aplicar identificación avanzada-condición aceptable para cada tipo de factor de riesgo identificado",I7="SI"),VLOOKUP(A7,'2'!$B$12:$M$212,9,FALSE)," ") -> 0 | AL7: =IF(AND(N7="Aplicar identificación avanzada-condición aceptable para cada tipo de factor de riesgo identificado",I7="SI"),VLOOKUP(A7,'2'!$B$12:$M$212,10,FALSE)," ") -> 0 | AM7: =IF(AND(N7="Aplicar identificación avanzada-condición aceptable para cada tipo de factor de riesgo identificado",J7="SI"),VLOOKUP(A7,'2'!$B$12:$M$212,2,FALSE)," ") -> area 3 | AN7: =IF(AND(N7="Aplicar identificación avanzada-condición aceptable para cada tipo de factor de riesgo identificado",J7="SI"),VLOOKUP(A7,'2'!$B$12:$M$212,3,FALSE)," ") -> puesto 3 | AO7: =IF(AND(N7="Aplicar identificación avanzada-condición aceptable para cada tipo de factor de riesgo identificado",J7="SI"),VLOOKUP(A7,'2'!$B$12:$M$212,4,FALSE)," ") -> tarea 3 | AP7: =IF(AND(N7="Aplicar identificación avanzada-condición aceptable para cada tipo de factor de riesgo identificado",J7="SI"),VLOOKUP(A7,'2'!$B$12:$M$212,6,FALSE)," ") -> 0 | AQ7: =IF(AND(N7="Aplicar identificación avanzada-condición aceptable para cada tipo de factor de riesgo identificado",J7="SI"),VLOOKUP(A7,'2'!$B$12:$M$212,7,FALSE)," ") -> 0 | AR7: =IF(AND(N7="Aplicar identificación avanzada-condición aceptable para cada tipo de factor de riesgo identificado",J7="SI"),VLOOKUP(A7,'2'!$B$12:$M$212,8,FALSE)," ") -> 0 | AS7: =IF(AND(N7="Aplicar identificación avanzada-condición aceptable para cada tipo de factor de riesgo identificado",J7="SI"),VLOOKUP(A7,'2'!$B$12:$M$212,9,FALSE)," ") -> 0 | AT7: =IF(AND(N7="Aplicar identificación avanzada-condición aceptable para cada tipo de factor de riesgo identificado",J7="SI"),VLOOKUP(A7,'2'!$B$12:$M$212,10,FALSE)," ") -> 0 | AU7: =IF(AND(N7="Aplicar identificación avanzada-condición aceptable para cada tipo de factor de riesgo identificado",K7="SI"),VLOOKUP(A7,'2'!$B$12:$M$212,2,FALSE)," ") -> area 3 | AV7: =IF(AND(N7="Aplicar identificación avanzada-condición aceptable para cada tipo de factor de riesgo identificado",K7="SI"),VLOOKUP(A7,'2'!$B$12:$M$212,3,FALSE)," ") -> puesto 3 | AW7: =IF(AND(N7="Aplicar identificación avanzada-condición aceptable para cada tipo de factor de riesgo identificado",K7="SI"),VLOOKUP(A7,'2'!$B$12:$M$212,4,FALSE)," ") -> tarea 3 | AX7: =IF(AND(N7="Aplicar identificación avanzada-condición aceptable para cada tipo de factor de riesgo identificado",K7="SI"),VLOOKUP(A7,'2'!$B$12:$M$212,6,FALSE)," ") -> 0 | AY7: =IF(AND(N7="Aplicar identificación avanzada-condición aceptable para cada tipo de factor de riesgo identificado",K7="SI"),VLOOKUP(A7,'2'!$B$12:$M$212,7,FALSE)," ") -> 0 | AZ7: =IF(AND(N7="Aplicar identificación avanzada-condición aceptable para cada tipo de factor de riesgo identificado",K7="SI"),VLOOKUP(A7,'2'!$B$12:$M$212,8,FALSE)," ") -> 0 | BA7: =IF(AND(N7="Aplicar identificación avanzada-condición aceptable para cada tipo de factor de riesgo identificado",K7="SI"),VLOOKUP(A7,'2'!$B$12:$M$212,9,FALSE)," ") -> 0 | BB7: =IF(AND(N7="Aplicar identificación avanzada-condición aceptable para cada tipo de factor de riesgo identificado",K7="SI"),VLOOKUP(A7,'2'!$B$12:$M$212,10,FALSE)," ") -> 0 | BC7: =IF(AND(N7="Aplicar identificación avanzada-condición aceptable para cada tipo de factor de riesgo identificado",L7="SI"),VLOOKUP(A7,'2'!$B$12:$M$212,2,FALSE)," ") -> area 3 | BD7: =IF(AND(N7="Aplicar identificación avanzada-condición aceptable para cada tipo de factor de riesgo identificado",L7="SI"),VLOOKUP(A7,'2'!$B$12:$M$212,3,FALSE)," ") -> puesto 3 | BE7: =IF(AND(N7="Aplicar identificación avanzada-condición aceptable para cada tipo de factor de riesgo identificado",L7="SI"),VLOOKUP(A7,'2'!$B$12:$M$212,4,FALSE)," ") -> tarea 3 | BF7: =IF(AND(N7="Aplicar identificación avanzada-condición aceptable para cada tipo de factor de riesgo identificado",L7="SI"),VLOOKUP(A7,'2'!$B$12:$M$212,6,FALSE)," ") -> 0 | BG7: =IF(AND(N7="Aplicar identificación avanzada-condición aceptable para cada tipo de factor de riesgo identificado",L7="SI"),VLOOKUP(A7,'2'!$B$12:$M$212,7,FALSE)," ") -> 0 | BH7: =IF(AND(N7="Aplicar identificación avanzada-condición aceptable para cada tipo de factor de riesgo identificado",L7="SI"),VLOOKUP(A7,'2'!$B$12:$M$212,8,FALSE)," ") -> 0 | BI7: =IF(AND(N7="Aplicar identificación avanzada-condición aceptable para cada tipo de factor de riesgo identificado",L7="SI"),VLOOKUP(A7,'2'!$B$12:$M$212,9,FALSE)," ") -> 0 | BJ7: =IF(AND(N7="Aplicar identificación avanzada-condición aceptable para cada tipo de factor de riesgo identificado",L7="SI"),VLOOKUP(A7,'2'!$B$12:$M$212,10,FALSE)," ") -> 0 | BK7: =IF(AND(N7="Aplicar identificación avanzada-condición aceptable para cada tipo de factor de riesgo identificado",M7="SI"),VLOOKUP(A7,'2'!$B$12:$M$212,2,FALSE)," ") -> area 3 | BL7: =IF(AND(N7="Aplicar identificación avanzada-condición aceptable para cada tipo de factor de riesgo identificado",M7="SI"),VLOOKUP(A7,'2'!$B$12:$M$212,3,FALSE)," ") -> puesto 3 | BM7: =IF(AND(N7="Aplicar identificación avanzada-condición aceptable para cada tipo de factor de riesgo identificado",M7="SI"),VLOOKUP(A7,'2'!$B$12:$M$212,4,FALSE)," ") -> tarea 3 | BN7: =IF(AND(N7="Aplicar identificación avanzada-condición aceptable para cada tipo de factor de riesgo identificado",M7="SI"),VLOOKUP(A7,'2'!$B$12:$M$212,6,FALSE)," ") -> 0 | BO7: =IF(AND(N7="Aplicar identificación avanzada-condición aceptable para cada tipo de factor de riesgo identificado",M7="SI"),VLOOKUP(A7,'2'!$B$12:$M$212,7,FALSE)," ") -> 0 | BP7: =IF(AND(N7="Aplicar identificación avanzada-condición aceptable para cada tipo de factor de riesgo identificado",M7="SI"),VLOOKUP(A7,'2'!$B$12:$M$212,8,FALSE)," ") -> 0 | BQ7: =IF(AND(N7="Aplicar identificación avanzada-condición aceptable para cada tipo de factor de riesgo identificado",M7="SI"),VLOOKUP(A7,'2'!$B$12:$M$212,9,FALSE)," ") -> 0 | BR7: =IF(AND(N7="Aplicar identificación avanzada-condición aceptable para cada tipo de factor de riesgo identificado",M7="SI"),VLOOKUP(A7,'2'!$B$12:$M$212,10,FALSE)," ") -> 0
